[2023-12-22T08:19:21.252+0000] {taskinstance.py:1083} INFO - Dependencies all met for <TaskInstance: MySQL_to_Redshift_v2.s3_to_redshift_nps manual__2023-12-22T08:18:48.259528+00:00 [queued]>
[2023-12-22T08:19:21.265+0000] {taskinstance.py:1083} INFO - Dependencies all met for <TaskInstance: MySQL_to_Redshift_v2.s3_to_redshift_nps manual__2023-12-22T08:18:48.259528+00:00 [queued]>
[2023-12-22T08:19:21.266+0000] {taskinstance.py:1279} INFO - 
--------------------------------------------------------------------------------
[2023-12-22T08:19:21.266+0000] {taskinstance.py:1280} INFO - Starting attempt 1 of 2
[2023-12-22T08:19:21.266+0000] {taskinstance.py:1281} INFO - 
--------------------------------------------------------------------------------
[2023-12-22T08:19:21.291+0000] {taskinstance.py:1300} INFO - Executing <Task(S3ToRedshiftOperator): s3_to_redshift_nps> on 2023-12-22 08:18:48.259528+00:00
[2023-12-22T08:19:21.301+0000] {standard_task_runner.py:55} INFO - Started process 178 to run task
[2023-12-22T08:19:21.304+0000] {standard_task_runner.py:82} INFO - Running: ['***', 'tasks', 'run', 'MySQL_to_Redshift_v2', 's3_to_redshift_nps', 'manual__2023-12-22T08:18:48.259528+00:00', '--job-id', '122', '--raw', '--subdir', 'DAGS_FOLDER/MySQL_to_Redshift_v2.py', '--cfg-path', '/tmp/tmpzrukd2l9']
[2023-12-22T08:19:21.306+0000] {standard_task_runner.py:83} INFO - Job 122: Subtask s3_to_redshift_nps
[2023-12-22T08:19:21.381+0000] {task_command.py:388} INFO - Running <TaskInstance: MySQL_to_Redshift_v2.s3_to_redshift_nps manual__2023-12-22T08:18:48.259528+00:00 [running]> on host 17bd7117c067
[2023-12-22T08:19:21.469+0000] {taskinstance.py:1509} INFO - Exporting the following env vars:
AIRFLOW_CTX_DAG_OWNER=***
AIRFLOW_CTX_DAG_ID=MySQL_to_Redshift_v2
AIRFLOW_CTX_TASK_ID=s3_to_redshift_nps
AIRFLOW_CTX_EXECUTION_DATE=2023-12-22T08:18:48.259528+00:00
AIRFLOW_CTX_TRY_NUMBER=1
AIRFLOW_CTX_DAG_RUN_ID=manual__2023-12-22T08:18:48.259528+00:00
[2023-12-22T08:19:21.480+0000] {base.py:73} INFO - Using connection ID 'aws_conn_id' for task execution.
[2023-12-22T08:19:21.487+0000] {base.py:73} INFO - Using connection ID 'aws_conn_id' for task execution.
[2023-12-22T08:19:21.488+0000] {connection_wrapper.py:334} INFO - AWS Connection (conn_id='aws_conn_id', conn_type='aws') credentials retrieved from login and password.
[2023-12-22T08:19:21.501+0000] {s3_to_redshift.py:164} INFO - Executing COPY command...
[2023-12-22T08:19:21.510+0000] {base.py:73} INFO - Using connection ID 'redshift_dev_db' for task execution.
[2023-12-22T08:19:21.950+0000] {sql.py:375} INFO - Running statement: CREATE TABLE #nps (LIKE areazml.nps);, parameters: None
[2023-12-22T08:19:21.978+0000] {taskinstance.py:1768} ERROR - Task failed with exception
Traceback (most recent call last):
  File "/home/airflow/.local/lib/python3.7/site-packages/redshift_connector/core.py", line 1631, in execute
    ps = cache["ps"][key]
KeyError: ('CREATE TABLE #nps (LIKE areazml.nps);', ())

During handling of the above exception, another exception occurred:

Traceback (most recent call last):
  File "/home/airflow/.local/lib/python3.7/site-packages/airflow/providers/amazon/aws/transfers/s3_to_redshift.py", line 165, in execute
    redshift_hook.run(sql, autocommit=self.autocommit)
  File "/home/airflow/.local/lib/python3.7/site-packages/airflow/providers/common/sql/hooks/sql.py", line 349, in run
    self._run_command(cur, sql_statement, parameters)
  File "/home/airflow/.local/lib/python3.7/site-packages/airflow/providers/common/sql/hooks/sql.py", line 380, in _run_command
    cur.execute(sql_statement)
  File "/home/airflow/.local/lib/python3.7/site-packages/redshift_connector/cursor.py", line 240, in execute
    self._c.execute(self, operation, args)
  File "/home/airflow/.local/lib/python3.7/site-packages/redshift_connector/core.py", line 1701, in execute
    self.handle_messages(cursor)
  File "/home/airflow/.local/lib/python3.7/site-packages/redshift_connector/core.py", line 1969, in handle_messages
    raise self.error
redshift_connector.error.ProgrammingError: {'S': 'ERROR', 'C': '42P01', 'M': 'relation "areazml" does not exist', 'F': '../src/pg/src/backend/catalog/namespace.c', 'L': '283', 'R': 'LocalRangeVarGetRelid'}
[2023-12-22T08:19:21.989+0000] {taskinstance.py:1323} INFO - Marking task as UP_FOR_RETRY. dag_id=MySQL_to_Redshift_v2, task_id=s3_to_redshift_nps, execution_date=20231222T081848, start_date=20231222T081921, end_date=20231222T081921
[2023-12-22T08:19:22.210+0000] {standard_task_runner.py:105} ERROR - Failed to execute job 122 for task s3_to_redshift_nps ({'S': 'ERROR', 'C': '42P01', 'M': 'relation "areazml" does not exist', 'F': '../src/pg/src/backend/catalog/namespace.c', 'L': '283', 'R': 'LocalRangeVarGetRelid'}; 178)
[2023-12-22T08:19:22.254+0000] {local_task_job.py:208} INFO - Task exited with return code 1
[2023-12-22T08:19:22.276+0000] {taskinstance.py:2578} INFO - 0 downstream tasks scheduled from follow-on schedule check
