[2023-12-16T15:04:57.502+0000] {taskinstance.py:1083} INFO - Dependencies all met for <TaskInstance: MySQL_to_Redshift_v2.s3_to_redshift_nps manual__2023-01-27T00:00:00+00:00 [queued]>
[2023-12-16T15:04:57.532+0000] {taskinstance.py:1083} INFO - Dependencies all met for <TaskInstance: MySQL_to_Redshift_v2.s3_to_redshift_nps manual__2023-01-27T00:00:00+00:00 [queued]>
[2023-12-16T15:04:57.532+0000] {taskinstance.py:1279} INFO - 
--------------------------------------------------------------------------------
[2023-12-16T15:04:57.532+0000] {taskinstance.py:1280} INFO - Starting attempt 1 of 2
[2023-12-16T15:04:57.532+0000] {taskinstance.py:1281} INFO - 
--------------------------------------------------------------------------------
[2023-12-16T15:04:57.584+0000] {taskinstance.py:1300} INFO - Executing <Task(S3ToRedshiftOperator): s3_to_redshift_nps> on 2023-01-27 00:00:00+00:00
[2023-12-16T15:04:57.605+0000] {standard_task_runner.py:55} INFO - Started process 204 to run task
[2023-12-16T15:04:57.610+0000] {standard_task_runner.py:82} INFO - Running: ['***', 'tasks', 'run', 'MySQL_to_Redshift_v2', 's3_to_redshift_nps', 'manual__2023-01-27T00:00:00+00:00', '--job-id', '70', '--raw', '--subdir', 'DAGS_FOLDER/MySQL_to_Redshift_v2.py', '--cfg-path', '/tmp/tmpsgtfej5e']
[2023-12-16T15:04:57.612+0000] {standard_task_runner.py:83} INFO - Job 70: Subtask s3_to_redshift_nps
[2023-12-16T15:04:57.758+0000] {task_command.py:388} INFO - Running <TaskInstance: MySQL_to_Redshift_v2.s3_to_redshift_nps manual__2023-01-27T00:00:00+00:00 [running]> on host b4327137477b
[2023-12-16T15:04:58.277+0000] {taskinstance.py:1509} INFO - Exporting the following env vars:
AIRFLOW_CTX_DAG_OWNER=***
AIRFLOW_CTX_DAG_ID=MySQL_to_Redshift_v2
AIRFLOW_CTX_TASK_ID=s3_to_redshift_nps
AIRFLOW_CTX_EXECUTION_DATE=2023-01-27T00:00:00+00:00
AIRFLOW_CTX_TRY_NUMBER=1
AIRFLOW_CTX_DAG_RUN_ID=manual__2023-01-27T00:00:00+00:00
[2023-12-16T15:04:58.312+0000] {base.py:73} INFO - Using connection ID 'aws_conn_id' for task execution.
[2023-12-16T15:04:58.321+0000] {base.py:73} INFO - Using connection ID 'aws_conn_id' for task execution.
[2023-12-16T15:04:58.322+0000] {connection_wrapper.py:334} INFO - AWS Connection (conn_id='aws_conn_id', conn_type='aws') credentials retrieved from login and password.
[2023-12-16T15:04:58.336+0000] {s3_to_redshift.py:164} INFO - Executing COPY command...
[2023-12-16T15:04:58.350+0000] {base.py:73} INFO - Using connection ID 'redshift_dev_db' for task execution.
[2023-12-16T15:04:58.749+0000] {sql.py:375} INFO - Running statement: CREATE TABLE #nps (LIKE areazml.nps);, parameters: None
[2023-12-16T15:04:58.779+0000] {taskinstance.py:1768} ERROR - Task failed with exception
Traceback (most recent call last):
  File "/home/airflow/.local/lib/python3.7/site-packages/redshift_connector/core.py", line 1631, in execute
    ps = cache["ps"][key]
KeyError: ('CREATE TABLE #nps (LIKE areazml.nps);', ())

During handling of the above exception, another exception occurred:

Traceback (most recent call last):
  File "/home/airflow/.local/lib/python3.7/site-packages/airflow/providers/amazon/aws/transfers/s3_to_redshift.py", line 165, in execute
    redshift_hook.run(sql, autocommit=self.autocommit)
  File "/home/airflow/.local/lib/python3.7/site-packages/airflow/providers/common/sql/hooks/sql.py", line 349, in run
    self._run_command(cur, sql_statement, parameters)
  File "/home/airflow/.local/lib/python3.7/site-packages/airflow/providers/common/sql/hooks/sql.py", line 380, in _run_command
    cur.execute(sql_statement)
  File "/home/airflow/.local/lib/python3.7/site-packages/redshift_connector/cursor.py", line 240, in execute
    self._c.execute(self, operation, args)
  File "/home/airflow/.local/lib/python3.7/site-packages/redshift_connector/core.py", line 1701, in execute
    self.handle_messages(cursor)
  File "/home/airflow/.local/lib/python3.7/site-packages/redshift_connector/core.py", line 1969, in handle_messages
    raise self.error
redshift_connector.error.ProgrammingError: {'S': 'ERROR', 'C': '42P01', 'M': 'relation "areazml" does not exist', 'F': '../src/pg/src/backend/catalog/namespace.c', 'L': '283', 'R': 'LocalRangeVarGetRelid'}
[2023-12-16T15:04:58.788+0000] {taskinstance.py:1323} INFO - Marking task as UP_FOR_RETRY. dag_id=MySQL_to_Redshift_v2, task_id=s3_to_redshift_nps, execution_date=20230127T000000, start_date=20231216T150457, end_date=20231216T150458
[2023-12-16T15:04:58.829+0000] {standard_task_runner.py:105} ERROR - Failed to execute job 70 for task s3_to_redshift_nps ({'S': 'ERROR', 'C': '42P01', 'M': 'relation "areazml" does not exist', 'F': '../src/pg/src/backend/catalog/namespace.c', 'L': '283', 'R': 'LocalRangeVarGetRelid'}; 204)
[2023-12-16T15:04:58.887+0000] {local_task_job.py:208} INFO - Task exited with return code 1
[2023-12-16T15:04:58.907+0000] {taskinstance.py:2578} INFO - 0 downstream tasks scheduled from follow-on schedule check
